Workbook

Sheet 26년 예상 매출 销售预计(法人别)
A1: 1. 26년 예상 매출 销售预计 (法人别)
A2: 区分 구분 | C2: 1月 | D2: 2月 | E2: 3月 | F2: 1Q | G2: 4月 | H2: 5月 | I2: 6月 | J2: 2Q | K2: 7月 | L2: 8月 | M2: 9月 | N2: 3Q | O2: 10月 | P2: 11月 | Q2: 12月 | R2: 4Q | S2: TOTAL | U2: 1Q 총 예상 매출 | V2: 1Q GZ 예상 매출
A3: TOTAL | B3: 25年 销售 25년 매출 | C3: =C8+C13 -> 103034.09 | D3: =D8+D13 -> 67773.028 | E3: =E8+E13 -> 82658.177 | F3: =F8+F13 -> 253465.3 | G3: =G8+G13 -> 73487.724 | H3: =H8+H13 -> 79158.287 | I3: =I8+I13 -> 69307.02 | J3: =J8+J13 -> 221953.03 | ... S3: =S8+S13 -> 998561.02 | U3: =F24 -> 270.68813 | V3: =F29 -> 197.93929
B4: 事业计划 사업계획 | C4: =C9+C14 -> 111900 | D4: =D9+D14 -> 76600 | E4: =E9+E14 -> 103000 | F4: =F9+F14 -> 291500 | G4: =G9+G14 -> 107000 | H4: =H9+H14 -> 115000 | I4: =I9+I14 -> 107000 | J4: =J9+J14 -> 329000 | ... S4: =S9+S14 -> 1350000 | U4: =F26 -> 0.067949472 | V4: =F31 -> 0.10174426
B5: 销售额 예상실적 | C5: =C10+C15 -> 112618.15 | D5: =D10+D15 -> 76846.4 | E5: =E10+E15 -> 81223.58 | F5: =F10+F15 -> 270688.13 | G5: =G10+G15 -> 96739 | H5: =H10+H15 -> 102887 | I5: =I10+I15 -> 93830 | J5: =J10+J15 -> 293456 | ... S5: =S10+S15 -> 564144.13
B6: 达成率 달성률 | C6: =C5/C4 -> 1.0064178 | D6: =D5/D4 -> 1.0032167 | E6: =E5/E4 -> 0.78857845 | F6: =F5/F4 -> 0.92860422 | G6: =G5/G4 -> 0.9041028 | H6: =H5/H4 -> 0.89466957 | I6: =I5/I4 -> 0.87691589 | J6: =J5/J4 -> 0.89196353 | ... S6: =S5/S4 -> 0.41788454
B7: 增长率 성장률 | C7: =C5/C3-1 -> 0.093018326 | D7: =D5/D3-1 -> 0.1338788 | E7: =E5/E3-1 -> -0.017355784 | F7: =F5/F3-1 -> 0.067949472 | G7: =G5/G3-1 -> 0.31639673 | H7: =H5/H3-1 -> 0.29976284 | I7: =I5/I3-1 -> 0.35383111 | J7: =J5/J3-1 -> 0.3221536 | ... S7: =S5/S3-1 -> -0.43504291
A8: GZ | B8: 25年 销售 25년 매출 | C8: 73498.602 | D8: 48798.088 | E8: 57363.234 | F8: =SUM(C8:E8) -> 179659.92 | G8: 52163.06 | H8: 49202.178 | I8: 39359.556 | J8: =SUM(G8:I8) -> 140724.79 | K8: 45616.638 | L8: 49067.628 | M8: 44577.118 | N8: =SUM(K8:M8) -> 139261.38 | O8: 55235.586 | P8: 48881.843 | Q8: 54632.028 | R8: =SUM(O8:Q8) -> 158749.46 | S8: =F8+J8+N8+R8 -> 618395.56
B9: 事业计划 사업계획 | C9: 82000 | D9: 53000 | E9: 73000 | F9: =SUM(C9:E9) -> 208000 | G9: 74000 | H9: 79000 | I9: 77000 | J9: =SUM(G9:I9) -> 230000 | K9: 70000 | L9: 73000 | M9: 78000 | N9: =SUM(K9:M9) -> 221000 | O9: 83000 | P9: 82000 | Q9: 76000 | R9: =SUM(O9:Q9) -> 241000 | S9: =F9+J9+N9+R9 -> 900000
B10: 销售额 예상실적 | C10: 82025.7 | D10: 52892.01 | E10: 63021.58 | F10: =SUM(C10:E10) -> 197939.29 | G10: 69189 | H10: 71487 | I10: 63830 | J10: =SUM(G10:I10) -> 204506 | N10: =SUM(K10:M10) -> 0 | R10: =SUM(O10:Q10) -> 0 | S10: =F10+J10+N10+R10 -> 402445.29
B11: 达成率 달성률 | C11: =C10/C9 -> 1.0003134 | D11: =D10/D9 -> 0.99796245 | E11: =E10/E9 -> 0.86330932 | F11: =F10/F9 -> 0.9516312 | G11: =G10/G9 -> 0.93498649 | H11: =H10/H9 -> 0.90489873 | I11: =I10/I9 -> 0.82896104 | J11: =J10/J9 -> 0.88915652 | ... S11: =S10/S9 -> 0.44716143
B12: 增长率 성장률 | C12: =C10/C8-1 -> 0.11601714 | D12: =D10/D8-1 -> 0.083895134 | E12: =E10/E8-1 -> 0.098640632 | F12: =F10/F8-1 -> 0.10174426 | G12: =G10/G8-1 -> 0.32639841 | H12: =H10/H8-1 -> 0.45292347 | I12: =I10/I8-1 -> 0.62171546 | J12: =J10/J8-1 -> 0.45323361 | ... S12: =S10/S8-1 -> -0.34921058
A13: YSGB | B13: 25年 销售 25년 매출 | C13: 29535.489 | D13: 18974.94 | E13: 25294.943 | F13: =SUM(C13:E13) -> 73805.373 | G13: 21324.664 | H13: 29956.109 | I13: 29947.464 | J13: =SUM(G13:I13) -> 81228.237 | K13: 27456.41 | L13: 38698.593 | M13: 44875.901 | N13: =SUM(K13:M13) -> 111030.9 | O13: 59101.543 | P13: 32198.257 | Q13: 22801.144 | R13: =SUM(O13:Q13) -> 114100.94 | S13: =F13+J13+N13+R13 -> 380165.46
B14: 事业计划 사업계획 | C14: 29900 | D14: 23600 | E14: 30000 | F14: =SUM(C14:E14) -> 83500 | G14: 33000 | H14: 36000 | I14: 30000 | J14: =SUM(G14:I14) -> 99000 | K14: 36000 | L14: 46000 | M14: 48000 | N14: =SUM(K14:M14) -> 130000 | O14: 57500 | P14: 41600 | Q14: 38400 | R14: =SUM(O14:Q14) -> 137500 | S14: =F14+J14+N14+R14 -> 450000
B15: 销售额 예상실적 | C15: 30592.45 | D15: 23954.39 | E15: 18202 | F15: =SUM(C15:E15) -> 72748.84 | G15: 27550 | H15: 31400 | I15: 30000 | J15: =SUM(G15:I15) -> 88950 | N15: =SUM(K15:M15) -> 0 | R15: =SUM(O15:Q15) -> 0 | S15: =F15+J15+N15+R15 -> 161698.84
B16: 达成率 달성률 | C16: =C15/C14 -> 1.0231589 | D16: =D15/D14 -> 1.0150165 | E16: =E15/E14 -> 0.60673333 | F16: =F15/F14 -> 0.87124359 | G16: =G15/G14 -> 0.83484848 | H16: =H15/H14 -> 0.87222222 | I16: =I15/I14 -> 1 | J16: =J15/J14 -> 0.89848485 | ... S16: =S15/S14 -> 0.35933076
B17: 增长率 성장률 | C17: =C15/C13-1 -> 0.035786132 | D17: =D15/D13-1 -> 0.26242242 | E17: =E15/E13-1 -> -0.28040953 | F17: =F15/F13-1 -> -0.014315118 | G17: =G15/G13-1 -> 0.29193126 | H17: =H15/H13-1 -> 0.048200226 | I17: =I15/I13-1 -> 0.0017542554 | J17: =J15/J13-1 -> 0.095062542 | ... S17: =S15/S13-1 -> -0.57466194
A21: 구 분 | C21: 1월 | D21: 2월 | E21: 3월 | F21: 1Q | G21: 4月 | H21: 5月 | I21: 6月 | J21: 2Q | K21: 7月 | L21: 8月 | M21: 9月 | N21: 3Q | O21: 10月 | P21: 11月 | Q21: 12月 | R21: 4Q | S21: TOTAL
A22: TOTAL | B22: 25년 매출 | C22: =C3/1000 -> 103.03409 | D22: =D3/1000 -> 67.773028 | E22: =E3/1000 -> 82.658177 | F22: =F3/1000 -> 253.4653 | G22: =G3/1000 -> 73.487724 | H22: =H3/1000 -> 79.158287 | I22: =I3/1000 -> 69.30702 | J22: =J3/1000 -> 221.95303 | ... S22: =S3/1000 -> 998.56102
B23: 사업계획 | C23: =C4/1000 -> 111.9 | D23: =D4/1000 -> 76.6 | E23: =E4/1000 -> 103 | F23: =F4/1000 -> 291.5 | G23: =G4/1000 -> 107 | H23: =H4/1000 -> 115 | I23: =I4/1000 -> 107 | J23: =J4/1000 -> 329 | ... S23: =S4/1000 -> 1350
B24: 예상실적 | C24: =C5/1000 -> 112.61815 | D24: =D5/1000 -> 76.8464 | E24: =E5/1000 -> 81.22358 | F24: =F5/1000 -> 270.68813 | G24: =G5/1000 -> 96.739 | H24: =H5/1000 -> 102.887 | I24: =I5/1000 -> 93.83 | J24: =J5/1000 -> 293.456 | ... M24: =M5/1000 -> 0 | N24: - | O24: =O5/1000 -> 0 | P24: =P5/1000 -> 0 | Q24: =Q5/1000 -> 0 | R24: - | S24: =S5/1000 -> 564.14413
B25: 달성률(%) | C25: =C24/C23 -> 1.0064178 | D25: =D24/D23 -> 1.0032167 | E25: =E24/E23 -> 0.78857845 | F25: =F24/F23 -> 0.92860422 | G25: =G24/G23 -> 0.9041028 | H25: =H24/H23 -> 0.89466957 | I25: =I24/I23 -> 0.87691589 | J25: =J24/J23 -> 0.89196353 | ... M25: =M24/M23 -> 0 | N25: - | O25: =O24/O23 -> 0 | P25: =P24/P23 -> 0 | Q25: =Q24/Q23 -> 0 | R25: - | S25: =S24/S23 -> 0.41788454
B26: 성장률(%) | C26: =C24/C22-1 -> 0.093018326 | D26: =D24/D22-1 -> 0.1338788 | E26: =E24/E22-1 -> -0.017355784 | F26: =F24/F22-1 -> 0.067949472 | G26: =G24/G22-1 -> 0.31639673 | H26: =H24/H22-1 -> 0.29976284 | I26: =I24/I22-1 -> 0.35383111 | J26: =J24/J22-1 -> 0.3221536 | ... M26: =M24/M22-1 -> -1 | N26: - | O26: =O24/O22-1 -> -1 | P26: =P24/P22-1 -> -1 | Q26: =Q24/Q22-1 -> -1 | R26: - | S26: =S24/S22-1 -> -0.43504291
A27: GZ | B27: 25년 매출 | C27: =C8/1000 -> 73.498602 | D27: =D8/1000 -> 48.798088 | E27: =E8/1000 -> 57.363234 | F27: =F8/1000 -> 179.65992 | G27: =G8/1000 -> 52.16306 | H27: =H8/1000 -> 49.202178 | I27: =I8/1000 -> 39.359556 | J27: =J8/1000 -> 140.72479 | ... S27: =S8/1000 -> 618.39556
B28: 사업계획 | C28: =C9/1000 -> 82 | D28: =D9/1000 -> 53 | E28: =E9/1000 -> 73 | F28: =F9/1000 -> 208 | G28: =G9/1000 -> 74 | H28: =H9/1000 -> 79 | I28: =I9/1000 -> 77 | J28: =J9/1000 -> 230 | ... S28: =S9/1000 -> 900
B29: 예상실적 | C29: =C10/1000 -> 82.0257 | D29: =D10/1000 -> 52.89201 | E29: =E10/1000 -> 63.02158 | F29: =F10/1000 -> 197.93929 | G29: =G10/1000 -> 69.189 | H29: =H10/1000 -> 71.487 | I29: =I10/1000 -> 63.83 | J29: =J10/1000 -> 204.506 | ... M29: =M10/1000 -> 0 | N29: - | O29: =O10/1000 -> 0 | P29: =P10/1000 -> 0 | Q29: =Q10/1000 -> 0 | R29: - | S29: =S10/1000 -> 402.44529
B30: 달성률(%) | C30: =C29/C28 -> 1.0003134 | D30: =D29/D28 -> 0.99796245 | E30: =E29/E28 -> 0.86330932 | F30: =F29/F28 -> 0.9516312 | G30: =G29/G28 -> 0.93498649 | H30: =H29/H28 -> 0.90489873 | I30: =I29/I28 -> 0.82896104 | J30: =J29/J28 -> 0.88915652 | ... M30: =M29/M28 -> 0 | N30: - | O30: =O29/O28 -> 0 | P30: =P29/P28 -> 0 | Q30: =Q29/Q28 -> 0 | R30: - | S30: =S29/S28 -> 0.44716143
B31: 성장률(%) | C31: =C29/C27-1 -> 0.11601714 | D31: =D29/D27-1 -> 0.083895134 | E31: =E29/E27-1 -> 0.098640632 | F31: =F29/F27-1 -> 0.10174426 | G31: =G29/G27-1 -> 0.32639841 | H31: =H29/H27-1 -> 0.45292347 | I31: =I29/I27-1 -> 0.62171546 | J31: =J29/J27-1 -> 0.45323361 | ... M31: =M29/M27-1 -> -1 | N31: - | O31: =O29/O27-1 -> -1 | P31: =P29/P27-1 -> -1 | Q31: =Q29/Q27-1 -> -1 | R31: - | S31: =S29/S27-1 -> -0.34921058
A32: YSGB | B32: 25년 매출 | C32: =C13/1000 -> 29.535489 | D32: =D13/1000 -> 18.97494 | E32: =E13/1000 -> 25.294943 | F32: =F13/1000 -> 73.805373 | G32: =G13/1000 -> 21.324664 | H32: =H13/1000 -> 29.956109 | I32: =I13/1000 -> 29.947464 | J32: =J13/1000 -> 81.228237 | ... S32: =S13/1000 -> 380.16546
B33: 사업계획 | C33: =C14/1000 -> 29.9 | D33: =D14/1000 -> 23.6 | E33: =E14/1000 -> 30 | F33: =F14/1000 -> 83.5 | G33: =G14/1000 -> 33 | H33: =H14/1000 -> 36 | I33: =I14/1000 -> 30 | J33: =J14/1000 -> 99 | ... S33: =S14/1000 -> 450
B34: 예상실적 | C34: =C15/1000 -> 30.59245 | D34: =D15/1000 -> 23.95439 | E34: =E15/1000 -> 18.202 | F34: =F15/1000 -> 72.74884 | G34: =G15/1000 -> 27.55 | H34: =H15/1000 -> 31.4 | I34: =I15/1000 -> 30 | J34: =J15/1000 -> 88.95 | ... M34: =M15/1000 -> 0 | N34: - | O34: =O15/1000 -> 0 | P34: =P15/1000 -> 0 | Q34: =Q15/1000 -> 0 | R34: - | S34: =S15/1000 -> 161.69884
B35: 달성률(%) | C35: =C34/C33 -> 1.0231589 | D35: =D34/D33 -> 1.0150165 | E35: =E34/E33 -> 0.60673333 | F35: =F34/F33 -> 0.87124359 | G35: =G34/G33 -> 0.83484848 | H35: =H34/H33 -> 0.87222222 | I35: =I34/I33 -> 1 | J35: =J34/J33 -> 0.89848485 | ... M35: =M34/M33 -> 0 | N35: - | O35: =O34/O33 -> 0 | P35: =P34/P33 -> 0 | Q35: =Q34/Q33 -> 0 | R35: - | S35: =S34/S33 -> 0.35933076
B36: 성장률(%) | C36: =C34/C32-1 -> 0.035786132 | D36: =D34/D32-1 -> 0.26242242 | E36: =E34/E32-1 -> -0.28040953 | F36: =F34/F32-1 -> -0.014315118 | G36: =G34/G32-1 -> 0.29193126 | H36: =H34/H32-1 -> 0.048200226 | I36: =I34/I32-1 -> 0.0017542554 | J36: =J34/J32-1 -> 0.095062542 | ... M36: =M34/M32-1 -> -1 | N36: - | O36: =O34/O32-1 -> -1 | P36: =P34/P32-1 -> -1 | Q36: =Q34/Q32-1 -> -1 | R36: - | S36: =S34/S32-1 -> -0.57466194

Sheet 26년 고객사별 예상 매출 销售预计(客户别)
A1: 2. 26년 3月 누적 예상 매출 累计销售预计(客户别) | D1: 26年1-2月首次上市 | O1: 3-1. 채널별 월별 매출
D2: 26年3月首次上市 | F2: =SUBTOTAL(9,F4:F9995) -> 618395.53 | G2: =SUBTOTAL(9,G4:G9995) -> 179659.96 | H2: =SUBTOTAL(9,H4:H9995) -> 900000 | I2: =SUBTOTAL(9,I4:I9995) -> 197939.3
A3: 排名 | B3: 客户 고객 | C3: 渠道 채널 | D3: 新客户(Y,N) | E3: 3,4线(Y,N) | F3: 25年销售 | G3: 25年销售(同期) | H3: 26年事业计划 | I3: 1Q 销售 매출액 | J3: 25年比排名 | K3: 25年1Q 排名 | M3: 3,4线(Y,N) | Q3: 25년 1월 | R3: 25년 2월 | S3: 25년 3월 | T3: 25년 1Q | U3: 25년 4월 | V3: 25년 5월 | W3: 25년 6월 | X3: 25년 2Q | Y3: 25년 7월 | Z3: 25년 8월 | AA3: 25년 9월 | AB3: 25년 3Q | AC3: 25년 10월 | AD3: 25년 11월 | AE3: 25년 12월 | AF3: 25년 4Q | AG3: Total
A4: =RANK(I4,$I$4:$I$999) -> 1 | B4: ZPX | C4: 线上 | D4: N | E4: =IF(M4=" 三线城市及其他 ","Y","N") -> N | F4: 120257.59 | G4: 31693.41 | H4: 90000 | I4: 33345.337 | J4: =IF(K4="","-",IF(A4=K4,"-",IF(A4<K4,"▲"&K4-A4,"▼"&A4-K4))) -> - | K4: =RANK(G4,$G$4:$G$999) -> 1 | M4: 二线城市 | O4: 온라인 | P4: 线上 | Q4: 37359 | R4: 24692 | S4: 24977 | T4: =SUM(Q4:S4) -> 87028 | U4: 25450 | V4: 24665 | W4: 8686 | X4: =SUM(U4:W4) -> 58801 | Y4: 17192 | Z4: 26962 | AA4: 17293 | AB4: =SUM(Y4:AA4) -> 61447 | AC4: 23296 | AD4: 13954 | AE4: 20891 | AF4: =SUM(AC4:AE4) -> 58141 | AG4: =SUM(T4,X4,AB4,AF4) -> 265417 | AH4: =MID(3,2,5)
A5: =RANK(I5,$I$4:$I$999) -> 2 | B5: GFM | C5: 出口 | D5: N | E5: =IF(M5=" 三线城市及其他 ","Y","N") -> N | F5: 66437.82 | G5: 13253.18 | H5: 70000 | I5: 27577.897 | J5: =IF(K5="","-",IF(A5=K5,"-",IF(A5<K5,"▲"&K5-A5,"▼"&A5-K5))) -> ▲1 | K5: =RANK(G5,$G$4:$G$999) -> 3 | M5: 一线城市 | O5: 왕홍 | P5: 红人 | Q5: 20167 | R5: 12642 | S5: 18416 | T5: =SUM(Q5:S5) -> 51225 | U5: 13641 | V5: 12311 | W5: 17853 | X5: =SUM(U5:W5) -> 43805 | Y5: 12085 | Z5: 8407 | AA5: 10551 | AB5: =SUM(Y5:AA5) -> 31043 | AC5: 12264 | AD5: 16524 | AE5: 10441 | AF5: =SUM(AC5:AE5) -> 39229 | AG5: =SUM(T5,X5,AB5,AF5) -> 165302
A6: =RANK(I6,$I$4:$I$999) -> 3 | B6: GYM | C6: 线上 | D6: N | E6: =IF(M6=" 三线城市及其他 ","Y","N") -> N | F6: -1576.3 | G6: 15061.76 | H6: 50000 | I6: 16293.396 | J6: =IF(K6="","-",IF(A6=K6,"-",IF(A6<K6,"▲"&K6-A6,"▼"&A6-K6))) -> ▼1 | K6: =RANK(G6,$G$4:$G$999) -> 2 | M6: 一线城市 | O6: 오프라인 | P6: 线下 | Q6: 7062 | R6: 3158 | S6: 5526 | T6: =SUM(Q6:S6) -> 15746 | U6: 4328 | V6: 2841 | W6: 3643 | X6: =SUM(U6:W6) -> 10812 | Y6: 6365 | Z6: 4077 | AA6: 7640 | AB6: =SUM(Y6:AA6) -> 18082 | AC6: 9386 | AD6: 10468 | AE6: 9083 | AF6: =SUM(AC6:AE6) -> 28937 | AG6: =SUM(T6,X6,AB6,AF6) -> 73577
A7: =RANK(I7,$I$4:$I$999) -> 4 | B7: YBA | C7: 线上 | D7: N | E7: =IF(M7=" 三线城市及其他 ","Y","N") -> N | F7: 27224.18 | G7: 7806.35 | H7: 30000 | I7: 15339.341 | J7: =IF(K7="","-",IF(A7=K7,"-",IF(A7<K7,"▲"&K7-A7,"▼"&A7-K7))) -> ▲3 | K7: =RANK(G7,$G$4:$G$999) -> 7 | M7: 二线城市 | O7: 수출 | P7: 出口 | Q7: 5263 | R7: 4532 | S7: 4214 | T7: =SUM(Q7:S7) -> 14009 | U7: 5392 | V7: 5763 | W7: 4860 | X7: =SUM(U7:W7) -> 16015 | Y7: 5302 | Z7: 3344 | AA7: 3895 | AB7: =SUM(Y7:AA7) -> 12541 | AC7: 7153 | AD7: 5159 | AE7: 14339 | AF7: =SUM(AC7:AE7) -> 26651 | AG7: =SUM(T7,X7,AB7,AF7) -> 69216
A8: =RANK(I8,$I$4:$I$999) -> 5 | B8: SAM | C8: 线下 | D8: N | E8: =IF(M8=" 三线城市及其他 ","Y","N") -> N | F8: 21123.13 | G8: 6138.96 | H8: 30000 | I8: 8940.2953 | J8: =IF(K8="","-",IF(A8=K8,"-",IF(A8<K8,"▲"&K8-A8,"▼"&A8-K8))) -> ▲5 | K8: =RANK(G8,$G$4:$G$999) -> 10 | M8: 一线城市 | O8: 합 | P8: TOTAL | Q8: =SUM(Q4:Q7) -> 69851 | R8: =SUM(R4:R7) -> 45024 | S8: =SUM(S4:S7) -> 53133 | T8: =SUM(Q8:S8) -> 168008 | U8: =SUM(U4:U7) -> 48811 | V8: =SUM(V4:V7) -> 45580 | W8: =SUM(W4:W7) -> 35042 | X8: =SUM(U8:W8) -> 129433 | Y8: =SUM(Y4:Y7) -> 40944 | Z8: =SUM(Z4:Z7) -> 42790 | AA8: =SUM(AA4:AA7) -> 39379 | AB8: =SUM(Y8:AA8) -> 123113 | AC8: =SUM(AC4:AC7) -> 52099 | AD8: =SUM(AD4:AD7) -> 46105 | AE8: =SUM(AE4:AE7) -> 54754 | AF8: =SUM(AC8:AE8) -> 152958 | AG8: =SUM(AG4:AG7) -> 573512
A9: =RANK(I9,$I$4:$I$999) -> 6 | B9: YJJ | C9: 线上 | D9: N | E9: =IF(M9=" 三线城市及其他 ","Y","N") -> N | F9: 989.38 | G9: 122.1 | H9: 5000 | I9: 8345.371 | J9: =IF(K9="","-",IF(A9=K9,"-",IF(A9<K9,"▲"&K9-A9,"▼"&A9-K9))) -> ▲83 | K9: =RANK(G9,$G$4:$G$999) -> 89 | M9: 一线城市
A10: =RANK(I10,$I$4:$I$999) -> 7 | B10: DTA | C10: 线上 | D10: N | E10: =IF(M10=" 三线城市及其他 ","Y","N") -> Y | F10: 30994.68 | G10: 6662.84 | H10: 35000 | I10: 7614.7977 | J10: =IF(K10="","-",IF(A10=K10,"-",IF(A10<K10,"▲"&K10-A10,"▼"&A10-K10))) -> ▲1 | K10: =RANK(G10,$G$4:$G$999) -> 8 | M10: 三线城市及其他
A11: =RANK(I11,$I$4:$I$999) -> 8 | B11: GRO | C11: 出口 | D11: N | E11: =IF(M11=" 三线城市及其他 ","Y","N") -> N | F11: 18.26 | G11: 0 | H11: 50000 | I11: 6984.4407 | J11: =IF(K11="","-",IF(A11=K11,"-",IF(A11<K11,"▲"&K11-A11,"▼"&A11-K11))) -> ▲113 | K11: =RANK(G11,$G$4:$G$999) -> 121 | M11: 二线城市 | O11: 3. 채널별 매출 비중
A12: =RANK(I12,$I$4:$I$999) -> 9 | B12: WDL | C12: 红人 | D12: N | E12: =IF(M12=" 三线城市及其他 ","Y","N") -> N | F12: 10543.26 | G12: 2370.4 | H12: 50000 | I12: 4097.2762 | J12: =IF(K12="","-",IF(A12=K12,"-",IF(A12<K12,"▲"&K12-A12,"▼"&A12-K12))) -> ▲7 | K12: =RANK(G12,$G$4:$G$999) -> 16 | M12: 一线城市
A13: =RANK(I13,$I$4:$I$999) -> 10 | B13: CGO | C13: 线上 | D13: Y | E13: =IF(M13=" 三线城市及其他 ","Y","N") -> N | F13: 315.79 | G13: 0 | H13: 100000 | I13: 4089.1487 | J13: =IF(K13="","-",IF(A13=K13,"-",IF(A13<K13,"▲"&K13-A13,"▼"&A13-K13))) -> ▲111 | K13: =RANK(G13,$G$4:$G$999) -> 121 | M13: 一线城市 | Q13: 25年销售（1~12月） | S13: 비중 | T13: 26年销售（1~3月） | V13: 계획비달성 | W13: 비중 | X13: 전년대비 비중
A14: =RANK(I14,$I$4:$I$999) -> 11 | B14: JV-其他 | C14: / | D14: N | E14: =IF(M14=" 三线城市及其他 ","Y","N") -> N | F14: 40255.42 | G14: 9610.27 | H14: 0 | I14: 4023.7344 | J14: =IF(K14="","-",IF(A14=K14,"-",IF(A14<K14,"▲"&K14-A14,"▼"&A14-K14))) -> ▼6 | K14: =RANK(G14,$G$4:$G$999) -> 5 | M14: / | O14: 온라인 | P14: 线上 | Q14: =AG4 -> 265417 | S14: =Q14/$Q$18*100 -> 46.279241 | T14: =SUMIF(C:C, '26년 고객사별 예상 매출 销售预计(客户别)'!P14, I:I) -> 109031.98 | V14: =T14/Q22*100 -> 23.198293 | W14: =T14/$T$18*100 -> 56.858311 | X14: =W14-S14 -> 10.57907
A15: =RANK(I15,$I$4:$I$999) -> 12 | B15: ATA | C15: 红人 | D15: N | E15: =IF(M15=" 三线城市及其他 ","Y","N") -> N | F15: 17704.79 | G15: 5836.88 | H15: 23000 | I15: 3410.0401 | J15: =IF(K15="","-",IF(A15=K15,"-",IF(A15<K15,"▲"&K15-A15,"▼"&A15-K15))) -> ▼1 | K15: =RANK(G15,$G$4:$G$999) -> 11 | M15: 一线城市 | O15: 왕홍 | P15: 红人 | Q15: =AG5 -> 165302 | S15: =Q15/$Q$18*100 -> 28.822762 | T15: =SUMIF(C:C, '26년 고객사별 예상 매출 销售预计(客户别)'!P15, I:I) -> 23507.825 | V15: =T15/Q23*100 -> 12.055295 | W15: =T15/$T$18*100 -> 12.258929 | X15: =W15-S15 -> -16.563834
A16: =RANK(I16,$I$4:$I$999) -> 13 | B16: ZIF | C16: 红人 | D16: N | E16: =IF(M16=" 三线城市及其他 ","Y","N") -> N | F16: 6958.83 | G16: 896.29 | H16: 15000 | I16: 3385.9004 | J16: =IF(K16="","-",IF(A16=K16,"-",IF(A16<K16,"▲"&K16-A16,"▼"&A16-K16))) -> ▲19 | K16: =RANK(G16,$G$4:$G$999) -> 32 | M16: 一线城市 | O16: 오프라인 | P16: 线下 | Q16: =AG6 -> 73577 | S16: =Q16/$Q$18*100 -> 12.8292 | T16: =SUMIF(C:C, '26년 고객사별 예상 매출 销售预计(客户别)'!P16, I:I) -> 23994.728 | V16: =T16/Q24*100 -> 21.813389 | W16: =T16/$T$18*100 -> 12.51284 | X16: =W16-S16 -> -0.31635952
A17: =RANK(I17,$I$4:$I$999) -> 14 | B17: MNS | C17: 线下 | D17: N | E17: =IF(M17=" 三线城市及其他 ","Y","N") -> N | F17: 20159.86 | G17: 1877.28 | H17: 30000 | I17: 2803.6095 | J17: =IF(K17="","-",IF(A17=K17,"-",IF(A17<K17,"▲"&K17-A17,"▼"&A17-K17))) -> ▲5 | K17: =RANK(G17,$G$4:$G$999) -> 19 | M17: 一线城市 | O17: 수출 | P17: 出口 | Q17: =AG7 -> 69216 | S17: =Q17/$Q$18*100 -> 12.068797 | T17: =SUMIF(C:C, '26년 고객사별 예상 매출 销售预计(客户别)'!P17, I:I) -> 35226.315 | V17: =T17/Q25*100 -> 28.181052 | W17: =T17/$T$18*100 -> 18.369921 | X17: =W17-S17 -> 6.3011234
A18: =RANK(I18,$I$4:$I$999) -> 15 | B18: CIY | C18: 线上 | D18: N | E18: =IF(M18=" 三线城市及其他 ","Y","N") -> N | F18: 2727.06 | G18: 921.5 | H18: 0 | I18: 2794.7134 | J18: =IF(K18="","-",IF(A18=K18,"-",IF(A18<K18,"▲"&K18-A18,"▼"&A18-K18))) -> ▲16 | K18: =RANK(G18,$G$4:$G$999) -> 31 | M18: 一线城市 | Q18: =SUM(Q14:Q17) -> 573512 | T18: =SUM(T14:T17) -> 191760.85 | AK18: 3월 결책회의 신고객(3월이후)
A19: =RANK(I19,$I$4:$I$999) -> 16 | B19: WXJ | C19: 线下 | D19: N | E19: =IF(M19=" 三线城市及其他 ","Y","N") -> Y | F19: 198.03 | G19: 0.99 | H19: 0 | I19: 2681.8928 | J19: =IF(K19="","-",IF(A19=K19,"-",IF(A19<K19,"▲"&K19-A19,"▼"&A19-K19))) -> ▲103 | K19: =RANK(G19,$G$4:$G$999) -> 119 | M19: 三线城市及其他 | O19: 4. 채널별 사업계획 | AK19: DDD
A20: =RANK(I20,$I$4:$I$999) -> 17 | B20: HLR | C20: 线上 | D20: N | E20: =IF(M20=" 三线城市及其他 ","Y","N") -> Y | F20: 3361.97 | G20: 0 | H20: 20000 | I20: 2456.1449 | J20: =IF(K20="","-",IF(A20=K20,"-",IF(A20<K20,"▲"&K20-A20,"▼"&A20-K20))) -> ▲104 | K20: =RANK(G20,$G$4:$G$999) -> 121 | M20: 三线城市及其他 | AK20: XHN
A21: =RANK(I21,$I$4:$I$999) -> 18 | B21: 其他 | C21: / | D21: N | E21: =IF(M21=" 三线城市及其他 ","Y","N") -> N | F21: 5070.66 | G21: 2485.51 | H21: 0 | I21: 2154.7178 | J21: =IF(K21="","-",IF(A21=K21,"-",IF(A21<K21,"▲"&K21-A21,"▼"&A21-K21))) -> ▼4 | K21: =RANK(G21,$G$4:$G$999) -> 14 | M21: / | Q21: 26年 | AK21: ZLO
A22: =RANK(I22,$I$4:$I$999) -> 19 | B22: MIN | C22: 红人 | D22: N | E22: =IF(M22=" 三线城市及其他 ","Y","N") -> N | F22: 19890.63 | G22: 6601.73 | H22: 20000 | I22: 1791.623 | J22: =IF(K22="","-",IF(A22=K22,"-",IF(A22<K22,"▲"&K22-A22,"▼"&A22-K22))) -> ▼10 | K22: =RANK(G22,$G$4:$G$999) -> 9 | M22: 一线城市 | O22: 온라인 | P22: 线上 | Q22: 470000 | AK22: DYL
A23: =RANK(I23,$I$4:$I$999) -> 20 | B23: JJH | C23: 红人 | D23: N | E23: =IF(M23=" 三线城市及其他 ","Y","N") -> N | F23: 35865.77 | G23: 10159.78 | H23: 0 | I23: 1734.2848 | J23: =IF(K23="","-",IF(A23=K23,"-",IF(A23<K23,"▲"&K23-A23,"▼"&A23-K23))) -> ▼16 | K23: =RANK(G23,$G$4:$G$999) -> 4 | M23: 二线城市 | O23: 왕홍 | P23: 红人 | Q23: 195000 | AK23: YMG
A24: =RANK(I24,$I$4:$I$999) -> 21 | B24: ZLS | C24: 线下 | D24: N | E24: =IF(M24=" 三线城市及其他 ","Y","N") -> N | F24: 4978.51 | G24: 1280.91 | H24: 0 | I24: 1673.4026 | J24: =IF(K24="","-",IF(A24=K24,"-",IF(A24<K24,"▲"&K24-A24,"▼"&A24-K24))) -> ▲2 | K24: =RANK(G24,$G$4:$G$999) -> 23 | M24: 一线城市 | O24: 오프라인 | P24: 线下 | Q24: 110000 | AK24: LPL
A25: =RANK(I25,$I$4:$I$999) -> 22 | B25: VCI | C25: 线上 | D25: N | E25: =IF(M25=" 三线城市及其他 ","Y","N") -> N | F25: 4920.39 | G25: 1388.41 | H25: 10000 | I25: 1605.9061 | J25: =IF(K25="","-",IF(A25=K25,"-",IF(A25<K25,"▲"&K25-A25,"▼"&A25-K25))) -> - | K25: =RANK(G25,$G$4:$G$999) -> 22 | M25: 二线城市 | O25: 수출 | P25: 出口 | Q25: 125000 | AK25: JFN
A26: =RANK(I26,$I$4:$I$999) -> 23 | B26: QIN | C26: 红人 | D26: N | E26: =IF(M26=" 三线城市及其他 ","Y","N") -> N | F26: 7285.87 | G26: 4307.86 | H26: 0 | I26: 1508.5946 | J26: =IF(K26="","-",IF(A26=K26,"-",IF(A26<K26,"▲"&K26-A26,"▼"&A26-K26))) -> ▼11 | K26: =RANK(G26,$G$4:$G$999) -> 12 | M26: 一线城市 | Q26: 900000 | AK26: WKK
A27: =RANK(I27,$I$4:$I$999) -> 24 | B27: KFZ | C27: 红人 | D27: N | E27: =IF(M27=" 三线城市及其他 ","Y","N") -> N | F27: 7956.63 | G27: 2427.51 | H27: 10000 | I27: 1407.9947 | J27: =IF(K27="","-",IF(A27=K27,"-",IF(A27<K27,"▲"&K27-A27,"▼"&A27-K27))) -> ▼9 | K27: =RANK(G27,$G$4:$G$999) -> 15 | M27: 一线城市 | AK27: XJM
A28: =RANK(I28,$I$4:$I$999) -> 25 | B28: SAT | C28: 线下 | D28: N | E28: =IF(M28=" 三线城市及其他 ","Y","N") -> N | F28: 2861.73 | G28: 0 | H28: 0 | I28: 1317.9053 | J28: =IF(K28="","-",IF(A28=K28,"-",IF(A28<K28,"▲"&K28-A28,"▼"&A28-K28))) -> ▲96 | K28: =RANK(G28,$G$4:$G$999) -> 121 | M28: 一线城市 | AK28: BAF
A29: =RANK(I29,$I$4:$I$999) -> 26 | B29: HZH | C29: 线上 | D29: Y | E29: =IF(M29=" 三线城市及其他 ","Y","N") -> N | F29: 0 | G29: 0 | H29: 0 | I29: 1231.7753 | J29: =IF(K29="","-",IF(A29=K29,"-",IF(A29<K29,"▲"&K29-A29,"▼"&A29-K29))) -> ▲95 | K29: =RANK(G29,$G$4:$G$999) -> 121 | M29: 一线城市 | AK29: SDH
A30: =RANK(I30,$I$4:$I$999) -> 27 | B30: JMS | C30: 红人 | D30: N | E30: =IF(M30=" 三线城市及其他 ","Y","N") -> N | F30: 6498.92 | G30: 1674.84 | H30: 7000 | I30: 1216.3255 | J30: =IF(K30="","-",IF(A30=K30,"-",IF(A30<K30,"▲"&K30-A30,"▼"&A30-K30))) -> ▼7 | K30: =RANK(G30,$G$4:$G$999) -> 20 | M30: 一线城市 | AK30: NXB
A31: =RANK(I31,$I$4:$I$999) -> 28 | B31: MZS | C31: 线上 | D31: N | E31: =IF(M31=" 三线城市及其他 ","Y","N") -> N | F31: 4261.25 | G31: 1116.31 | H31: 0 | I31: 1112.8484 | J31: =IF(K31="","-",IF(A31=K31,"-",IF(A31<K31,"▲"&K31-A31,"▼"&A31-K31))) -> - | K31: =RANK(G31,$G$4:$G$999) -> 28 | M31: 一线城市 | AK31: KATO
A32: =RANK(I32,$I$4:$I$999) -> 29 | B32: DSM | C32: 红人 | D32: N | E32: =IF(M32=" 三线城市及其他 ","Y","N") -> Y | F32: 359.05 | G32: 0 | H32: 0 | I32: 1075.7306 | J32: =IF(K32="","-",IF(A32=K32,"-",IF(A32<K32,"▲"&K32-A32,"▼"&A32-K32))) -> ▲92 | K32: =RANK(G32,$G$4:$G$999) -> 121 | M32: 三线城市及其他 | AK32: BSM
A33: =RANK(I33,$I$4:$I$999) -> 30 | B33: KZQ | C33: 红人 | D33: N | E33: =IF(M33=" 三线城市及其他 ","Y","N") -> N | F33: 798.42 | G33: 622.02 | H33: 0 | I33: 1013.3172 | J33: =IF(K33="","-",IF(A33=K33,"-",IF(A33<K33,"▲"&K33-A33,"▼"&A33-K33))) -> ▲10 | K33: =RANK(G33,$G$4:$G$999) -> 40 | M33: 二线城市 | AK33: GPN
A34: =RANK(I34,$I$4:$I$999) -> 31 | B34: DJD | C34: 线上 | D34: N | E34: =IF(M34=" 三线城市及其他 ","Y","N") -> N | F34: 2064.79 | G34: 530.98 | H34: 0 | I34: 923.80069 | J34: =IF(K34="","-",IF(A34=K34,"-",IF(A34<K34,"▲"&K34-A34,"▼"&A34-K34))) -> ▲14 | K34: =RANK(G34,$G$4:$G$999) -> 45 | M34: 一线城市 | AK34: PAC
A35: =RANK(I35,$I$4:$I$999) -> 32 | B35: PIM | C35: 线下 | D35: N | E35: =IF(M35=" 三线城市及其他 ","Y","N") -> N | F35: 512.8 | G35: 123.15 | H35: 0 | I35: 891.75856 | J35: =IF(K35="","-",IF(A35=K35,"-",IF(A35<K35,"▲"&K35-A35,"▼"&A35-K35))) -> ▲56 | K35: =RANK(G35,$G$4:$G$999) -> 88 | M35: 二线城市 | AK35: YBT
A36: =RANK(I36,$I$4:$I$999) -> 33 | B36: FUY | C36: 线上 | D36: N | E36: =IF(M36=" 三线城市及其他 ","Y","N") -> N | F36: 6751.84 | G36: 3554.26 | H36: 10000 | I36: 792.31651 | J36: =IF(K36="","-",IF(A36=K36,"-",IF(A36<K36,"▲"&K36-A36,"▼"&A36-K36))) -> ▼20 | K36: =RANK(G36,$G$4:$G$999) -> 13 | M36: 一线城市
A37: =RANK(I37,$I$4:$I$999) -> 34 | B37: ZDA | C37: 线上 | D37: N | E37: =IF(M37=" 三线城市及其他 ","Y","N") -> N | F37: 546.74 | G37: 165.84 | H37: 10000 | I37: 773.74415 | J37: =IF(K37="","-",IF(A37=K37,"-",IF(A37<K37,"▲"&K37-A37,"▼"&A37-K37))) -> ▲47 | K37: =RANK(G37,$G$4:$G$999) -> 81 | M37: 二线城市
A38: =RANK(I38,$I$4:$I$999) -> 35 | B38: ABL | C38: 线上 | D38: Y | E38: =IF(M38=" 三线城市及其他 ","Y","N") -> N | F38: 0 | G38: 0 | H38: 0 | I38: 754.05646 | J38: =IF(K38="","-",IF(A38=K38,"-",IF(A38<K38,"▲"&K38-A38,"▼"&A38-K38))) -> ▲86 | K38: =RANK(G38,$G$4:$G$999) -> 121 | M38: 二线城市
A39: =RANK(I39,$I$4:$I$999) -> 36 | B39: JYN | C39: 线上 | D39: N | E39: =IF(M39=" 三线城市及其他 ","Y","N") -> N | F39: 2268.82 | G39: 309.61 | H39: 0 | I39: 742.75431 | J39: =IF(K39="","-",IF(A39=K39,"-",IF(A39<K39,"▲"&K39-A39,"▼"&A39-K39))) -> ▲21 | K39: =RANK(G39,$G$4:$G$999) -> 57 | M39: 一线城市
A40: =RANK(I40,$I$4:$I$999) -> 37 | B40: NAS | C40: 线上 | D40: N | E40: =IF(M40=" 三线城市及其他 ","Y","N") -> N | F40: 2634.59 | G40: 781.96 | H40: 0 | I40: 711.80253 | J40: =IF(K40="","-",IF(A40=K40,"-",IF(A40<K40,"▲"&K40-A40,"▼"&A40-K40))) -> ▼1 | K40: =RANK(G40,$G$4:$G$999) -> 36 | M40: 一线城市
...

Sheet Sheet1
A1: 순위 | B1: 고객사 | C1: 채널 | D1: 신규처 | E1: 3,4선 | F1: 25년매출 | G1: 25년매출(동기) | H1: 사업계획 | I1: 예상매출 | J1: 전년대비순위 | K1: 25년매출 | L1: 사업계획 | M1: 25년매출(동기) | N1: 예상매출 | O1: 성장률 | P1: 사업계획비달성률 | Q1: 점유율 | R1: 전년대비순위
A2: 1 | B2: ZPX | C2: 线上 | F2: 120257.59 | G2: 31693.41 | H2: 90000 | I2: 33345.337 | J2: - | K2: =F2/1000 -> 120.25759 | L2: =H2/1000 -> 90 | M2: =IFERROR(G2/1000,0) -> 31.69341 | N2: =I2/1000 -> 33.345337 | O2: =(N2-M2)/M2 -> 0.0521221 | P2: =N2/L2 -> 0.37050375 | Q2: =Sheet1!I2/'26년 고객사별 예상 매출 销售预计(客户别)'!$I$2 -> 0.16846244 | R2: =J2 -> - | S2: =VLOOKUP(B2,$T$2:$T$31,1,0) -> ZPX | T2: CGO | U2: =VLOOKUP(T2,$B$2:$B$33,1,0) -> CGO
A3: 2 | B3: GFM | C3: 出口 | F3: 66437.82 | G3: 13253.18 | H3: 70000 | I3: 27577.897 | J3: ▲1 | K3: =F3/1000 -> 66.43782 | L3: =H3/1000 -> 70 | M3: =IFERROR(G3/1000,0) -> 13.25318 | N3: =I3/1000 -> 27.577897 | O3: =(N3-M3)/M3 -> 1.0808513 | P3: =N3/L3 -> 0.39396995 | Q3: =Sheet1!I3/'26년 고객사별 예상 매출 销售预计(客户别)'!$I$2 -> 0.13932502 | R3: =J3 -> ▲1 | S3: =VLOOKUP(B3,$T$2:$T$31,1,0) -> GFM | T3: ZPX | U3: =VLOOKUP(T3,$B$2:$B$33,1,0) -> ZPX
A4: 3 | B4: GYM | C4: 线上 | F4: -1576.3 | G4: 15061.76 | H4: 50000 | I4: 16293.396 | J4: ▼1 | K4: =F4/1000 -> -1.5763 | L4: =H4/1000 -> 50 | M4: =IFERROR(G4/1000,0) -> 15.06176 | N4: =I4/1000 -> 16.293396 | O4: - | P4: =N4/L4 -> 0.32586792 | Q4: =Sheet1!I4/'26년 고객사별 예상 매출 销售预计(客户别)'!$I$2 -> 0.082315116 | R4: =J4 -> ▼1 | S4: =VLOOKUP(B4,$T$2:$T$31,1,0) -> GYM | T4: GFM | U4: =VLOOKUP(T4,$B$2:$B$33,1,0) -> GFM
A5: 4 | B5: YBA | C5: 线上 | F5: 27224.18 | G5: 7806.35 | H5: 30000 | I5: 15339.341 | J5: ▲3 | K5: =F5/1000 -> 27.22418 | L5: =H5/1000 -> 30 | M5: =IFERROR(G5/1000,0) -> 7.80635 | N5: =I5/1000 -> 15.339341 | O5: =(N5-M5)/M5 -> 0.96498249 | P5: =N5/L5 -> 0.51131137 | Q5: =Sheet1!I5/'26년 고객사별 예상 매출 销售预计(客户别)'!$I$2 -> 0.077495178 | R5: =J5 -> ▲3 | S5: =VLOOKUP(B5,$T$2:$T$31,1,0) -> YBA | T5: GYM | U5: =VLOOKUP(T5,$B$2:$B$33,1,0) -> GYM
A6: 5 | B6: SAM | C6: 线下 | F6: 21123.13 | G6: 6138.96 | H6: 30000 | I6: 8940.2953 | J6: ▲5 | K6: =F6/1000 -> 21.12313 | L6: =H6/1000 -> 30 | M6: =IFERROR(G6/1000,0) -> 6.13896 | N6: =I6/1000 -> 8.9402953 | O6: - | P6: =N6/L6 -> 0.29800984 | Q6: =Sheet1!I6/'26년 고객사별 예상 매출 销售预计(客户别)'!$I$2 -> 0.045166854 | R6: =J6 -> ▲5 | S6: =VLOOKUP(B6,$T$2:$T$31,1,0) -> SAM | T6: WDL | U6: =VLOOKUP(T6,$B$2:$B$33,1,0) -> WDL
A7: 6 | B7: YJJ | C7: 线上 | F7: 989.38 | G7: 122.1 | H7: 5000 | I7: 8345.371 | J7: ▲83 | K7: =F7/1000 -> 0.98938 | L7: =H7/1000 -> 5 | M7: =IFERROR(G7/1000,0) -> 0.1221 | N7: =I7/1000 -> 8.345371 | O7: =(N7-M7)/M7 -> 67.348656 | P7: =N7/L7 -> 1.6690742 | Q7: =Sheet1!I7/'26년 고객사별 예상 매출 销售预计(客户别)'!$I$2 -> 0.042161264 | R7: =J7 -> ▲83 | S7: =VLOOKUP(B7,$T$2:$T$31,1,0) -> #N/A | T7: DTA | U7: =VLOOKUP(T7,$B$2:$B$33,1,0) -> DTA
A8: 7 | B8: DTA | C8: 线上 | E8: ★ | F8: 30994.68 | G8: 6662.84 | H8: 35000 | I8: 7614.7977 | J8: ▲1 | K8: =F8/1000 -> 30.99468 | L8: =H8/1000 -> 35 | M8: =IFERROR(G8/1000,0) -> 6.66284 | N8: =I8/1000 -> 7.6147978 | O8: - | P8: =N8/L8 -> 0.21756565 | Q8: =Sheet1!I8/'26년 고객사별 예상 매출 销售预计(客户别)'!$I$2 -> 0.038470369 | R8: =J8 -> ▲1 | S8: =VLOOKUP(B8,$T$2:$T$31,1,0) -> DTA | T8: YMG | U8: =VLOOKUP(T8,$B$2:$B$33,1,0) -> #N/A
A9: 8 | B9: GRO | C9: 出口 | F9: 18.26 | G9: 0 | H9: 50000 | I9: 6984.4407 | J9: ▲113 | K9: =F9/1000 -> 0.01826 | L9: =H9/1000 -> 50 | M9: =IFERROR(G9/1000,0) -> 0 | N9: =I9/1000 -> 6.9844407 | O9: =(N9-M9)/M9 -> #DIV/0! | P9: =N9/L9 -> 0.13968881 | Q9: =Sheet1!I9/'26년 고객사별 예상 매출 销售预计(客户别)'!$I$2 -> 0.035285771 | R9: =J9 -> ▲113 | S9: =VLOOKUP(B9,$T$2:$T$31,1,0) -> GRO | T9: YBA | U9: =VLOOKUP(T9,$B$2:$B$33,1,0) -> YBA
A10: 9 | B10: WDL | C10: 红人 | F10: 10543.26 | G10: 2370.4 | H10: 50000 | I10: 4097.2762 | J10: ▲7 | K10: =F10/1000 -> 10.54326 | L10: =H10/1000 -> 50 | M10: =IFERROR(G10/1000,0) -> 2.3704 | N10: =I10/1000 -> 4.0972762 | O10: =(N10-M10)/M10 -> 0.7285168 | P10: =N10/L10 -> 0.081945524 | Q10: =Sheet1!I10/'26년 고객사별 예상 매출 销售预计(客户别)'!$I$2 -> 0.02069966 | R10: =J10 -> ▲7 | S10: =VLOOKUP(B10,$T$2:$T$31,1,0) -> WDL | T10: DDY | U10: =VLOOKUP(T10,$B$2:$B$33,1,0) -> #N/A
A11: 10 | B11: CGO | C11: 线上 | D11: ● | F11: 315.79 | G11: 0 | H11: 100000 | I11: 4089.1487 | J11: ▲111 | K11: =F11/1000 -> 0.31579 | L11: =H11/1000 -> 100 | M11: =IFERROR(G11/1000,0) -> 0 | N11: =I11/1000 -> 4.0891487 | O11: - | P11: =N11/L11 -> 0.040891487 | Q11: =Sheet1!I11/'26년 고객사별 예상 매출 销售预计(客户别)'!$I$2 -> 0.020658599 | R11: =J11 -> ▲111 | S11: =VLOOKUP(B11,$T$2:$T$31,1,0) -> CGO | T11: ATA | U11: =VLOOKUP(T11,$B$2:$B$33,1,0) -> ATA
A12: 11 | B12: JV-其他 | C12: / | F12: 40255.42 | G12: 9610.27 | H12: 0 | I12: 4023.7344 | J12: ▼6 | K12: =F12/1000 -> 40.25542 | L12: =H12/1000 -> 0 | M12: =IFERROR(G12/1000,0) -> 9.61027 | N12: =I12/1000 -> 4.0237344 | O12: =(N12-M12)/M12 -> -0.58130891 | P12: =N12/L12 -> #DIV/0! | Q12: =Sheet1!I12/'26년 고객사별 예상 매출 销售预计(客户别)'!$I$2 -> 0.020328123 | R12: =J12 -> ▼6 | S12: =VLOOKUP(B12,$T$2:$T$31,1,0) -> #N/A | T12: XHN | U12: =VLOOKUP(T12,$B$2:$B$33,1,0) -> #N/A
A13: 11 | B13: ATA | C13: 红人 | F13: 17704.79 | G13: 5836.88 | H13: 23000 | I13: 3410.0401 | J13: ▼1 | K13: =F13/1000 -> 17.70479 | L13: =H13/1000 -> 23 | M13: =IFERROR(G13/1000,0) -> 5.83688 | N13: =I13/1000 -> 3.4100401 | O13: =(N13-M13)/M13 -> -0.4157769 | P13: =N13/L13 -> 0.14826262 | Q13: =Sheet1!I13/'26년 고객사별 예상 매출 销售预计(客户别)'!$I$2 -> 0.017227707 | R13: =J13 -> ▼1 | S13: =VLOOKUP(B13,$T$2:$T$31,1,0) -> ATA | T13: YWH | U13: =VLOOKUP(T13,$B$2:$B$33,1,0) -> #N/A
A14: 12 | B14: ZIF | C14: 红人 | F14: 6958.83 | G14: 896.29 | H14: 15000 | I14: 3385.9004 | J14: ▲19 | K14: =F14/1000 -> 6.95883 | L14: =H14/1000 -> 15 | M14: =IFERROR(G14/1000,0) -> 0.89629 | N14: =I14/1000 -> 3.3859004 | O14: =(N14-M14)/M14 -> 2.777684 | P14: =N14/L14 -> 0.22572669 | Q14: =Sheet1!I14/'26년 고객사별 예상 매출 销售预计(客户别)'!$I$2 -> 0.017105751 | R14: =J14 -> ▲19 | S14: =VLOOKUP(B14,$T$2:$T$31,1,0) -> ZIF | T14: GRO | U14: =VLOOKUP(T14,$B$2:$B$33,1,0) -> GRO
A15: 13 | B15: MNS | C15: 线下 | F15: 20159.86 | G15: 1877.28 | H15: 30000 | I15: 2803.6095 | J15: ▲5 | K15: =F15/1000 -> 20.15986 | L15: =H15/1000 -> 30 | M15: =IFERROR(G15/1000,0) -> 1.87728 | N15: =I15/1000 -> 2.8036095 | O15: =(N15-M15)/M15 -> 0.4934424 | P15: =N15/L15 -> 0.093453651 | Q15: =Sheet1!I15/'26년 고객사별 예상 매출 销售预计(客户别)'!$I$2 -> 0.014163987 | R15: =J15 -> ▲5 | S15: =VLOOKUP(B15,$T$2:$T$31,1,0) -> MNS | T15: SAM | U15: =VLOOKUP(T15,$B$2:$B$33,1,0) -> SAM
A16: 14 | B16: CIY | C16: 线上 | F16: 2727.06 | G16: 921.5 | H16: 0 | I16: 2794.7134 | J16: ▲16 | K16: =F16/1000 -> 2.72706 | L16: =H16/1000 -> 0 | M16: =IFERROR(G16/1000,0) -> 0.9215 | N16: =I16/1000 -> 2.7947134 | O16: - | P16: =N16/L16 -> #DIV/0! | Q16: =Sheet1!I16/'26년 고객사별 예상 매출 销售预计(客户别)'!$I$2 -> 0.014119043 | R16: =J16 -> ▲16 | S16: =VLOOKUP(B16,$T$2:$T$31,1,0) -> #N/A | T16: MNS | U16: =VLOOKUP(T16,$B$2:$B$33,1,0) -> MNS
A17: 15 | B17: WXJ | C17: 线下 | E17: ★ | F17: 198.03 | G17: 0.99 | H17: 0 | I17: 2681.8928 | J17: ▲103 | K17: =F17/1000 -> 0.19803 | L17: =H17/1000 -> 0 | M17: =IFERROR(G17/1000,0) -> 0.00099 | N17: =I17/1000 -> 2.6818928 | O17: - | P17: =N17/L17 -> #DIV/0! | Q17: =Sheet1!I17/'26년 고객사별 예상 매출 销售预计(客户别)'!$I$2 -> 0.013549067 | R17: =J17 -> ▲103 | S17: =VLOOKUP(B17,$T$2:$T$31,1,0) -> WXJ | T17: ZDA | U17: =VLOOKUP(T17,$B$2:$B$33,1,0) -> #N/A
A18: 16 | B18: HLR | C18: 线上 | E18: ★ | F18: 3361.97 | G18: 0 | H18: 20000 | I18: 2456.1449 | J18: ▲104 | K18: =F18/1000 -> 3.36197 | L18: =H18/1000 -> 20 | M18: =IFERROR(G18/1000,0) -> 0 | N18: =I18/1000 -> 2.4561449 | O18: - | P18: =N18/L18 -> 0.12280724 | Q18: =Sheet1!I18/'26년 고객사별 예상 매출 销售预计(客户别)'!$I$2 -> 0.012408576 | R18: =J18 -> ▲104 | S18: =VLOOKUP(B18,$T$2:$T$31,1,0) -> HLR | T18: GPL | U18: =VLOOKUP(T18,$B$2:$B$33,1,0) -> #N/A
A19: 16 | B19: 其他 | C19: / | F19: 5070.66 | G19: 2485.51 | H19: 0 | I19: 2154.7178 | J19: ▼4 | K19: =F19/1000 -> 5.07066 | L19: =H19/1000 -> 0 | M19: =IFERROR(G19/1000,0) -> 2.48551 | N19: =I19/1000 -> 2.1547178 | O19: =(N19-M19)/M19 -> -0.13308825 | P19: =N19/L19 -> #DIV/0! | Q19: =Sheet1!I19/'26년 고객사별 예상 매출 销售预计(客户别)'!$I$2 -> 0.010885751 | R19: =J19 -> ▼4 | S19: =VLOOKUP(B19,$T$2:$T$31,1,0) -> #N/A | T19: HLR | U19: =VLOOKUP(T19,$B$2:$B$33,1,0) -> HLR
A20: 17 | B20: MIN | C20: 红人 | F20: 19890.63 | G20: 6601.73 | H20: 20000 | I20: 1791.623 | J20: ▼10 | K20: =F20/1000 -> 19.89063 | L20: =H20/1000 -> 20 | M20: =IFERROR(G20/1000,0) -> 6.60173 | N20: =I20/1000 -> 1.791623 | O20: =(N20-M20)/M20 -> -0.7286131 | P20: =N20/L20 -> 0.089581152 | Q20: =Sheet1!I20/'26년 고객사별 예상 매출 销售预计(客户别)'!$I$2 -> 0.0090513762 | R20: =J20 -> ▼10 | S20: =VLOOKUP(B20,$T$2:$T$31,1,0) -> MIN | T20: XUK | U20: =VLOOKUP(T20,$B$2:$B$33,1,0) -> #N/A
A21: 18 | B21: JJH | C21: 红人 | F21: 35865.77 | G21: 10159.78 | H21: 0 | I21: 1734.2848 | J21: ▼16 | K21: =F21/1000 -> 35.86577 | L21: =H21/1000 -> 0 | M21: =IFERROR(G21/1000,0) -> 10.15978 | N21: =I21/1000 -> 1.7342848 | O21: =(N21-M21)/M21 -> -0.82929898 | P21: =N21/L21 -> #DIV/0! | Q21: =Sheet1!I21/'26년 고객사별 예상 매출 销售预计(客户别)'!$I$2 -> 0.0087617003 | R21: =J21 -> ▼16 | S21: =VLOOKUP(B21,$T$2:$T$31,1,0) -> #N/A | T21: ZIF | U21: =VLOOKUP(T21,$B$2:$B$33,1,0) -> ZIF
A22: 19 | B22: ZLS | C22: 线下 | F22: 4978.51 | G22: 1280.91 | H22: 0 | I22: 1673.4026 | J22: ▲2 | K22: =F22/1000 -> 4.97851 | L22: =H22/1000 -> 0 | M22: =IFERROR(G22/1000,0) -> 1.28091 | N22: =I22/1000 -> 1.6734026 | O22: =(N22-M22)/M22 -> 0.30641702 | P22: =N22/L22 -> #DIV/0! | Q22: =Sheet1!I22/'26년 고객사별 예상 매출 销售预计(客户别)'!$I$2 -> 0.0084541203 | R22: =J22 -> ▲2 | S22: =VLOOKUP(B22,$T$2:$T$31,1,0) -> #N/A | T22: DDD | U22: =VLOOKUP(T22,$B$2:$B$33,1,0) -> #N/A
A23: 20 | B23: VCI | C23: 线上 | F23: 4920.39 | G23: 1388.41 | H23: 10000 | I23: 1605.9061 | J23: - | K23: =F23/1000 -> 4.92039 | L23: =H23/1000 -> 10 | M23: =IFERROR(G23/1000,0) -> 1.38841 | N23: =I23/1000 -> 1.6059061 | O23: =(N23-M23)/M23 -> 0.1566512 | P23: =N23/L23 -> 0.16059061 | Q23: =Sheet1!I23/'26년 고객사별 예상 매출 销售预计(客户别)'!$I$2 -> 0.0081131241 | R23: =J23 -> - | S23: =VLOOKUP(B23,$T$2:$T$31,1,0) -> VCI | T23: MIN | U23: =VLOOKUP(T23,$B$2:$B$33,1,0) -> MIN
A24: 21 | B24: QIN | C24: 红人 | F24: 7285.87 | G24: 4307.86 | H24: 0 | I24: 1508.5946 | J24: ▼11 | K24: =F24/1000 -> 7.28587 | L24: =H24/1000 -> 0 | M24: =IFERROR(G24/1000,0) -> 4.30786 | N24: =I24/1000 -> 1.5085946 | O24: =(N24-M24)/M24 -> -0.64980417 | P24: =N24/L24 -> #DIV/0! | Q24: =Sheet1!I24/'26년 고객사별 예상 매출 销售预计(客户别)'!$I$2 -> 0.0076215012 | R24: =J24 -> ▼11 | S24: =VLOOKUP(B24,$T$2:$T$31,1,0) -> #N/A | T24: ZLO | U24: =VLOOKUP(T24,$B$2:$B$33,1,0) -> #N/A
A25: 22 | B25: KFZ | C25: 红人 | F25: 7956.63 | G25: 2427.51 | H25: 10000 | I25: 1407.9947 | J25: ▼9 | K25: =F25/1000 -> 7.95663 | L25: =H25/1000 -> 10 | M25: =IFERROR(G25/1000,0) -> 2.42751 | N25: =I25/1000 -> 1.4079947 | O25: - | P25: =N25/L25 -> 0.14079947 | Q25: =Sheet1!I25/'26년 고객사별 예상 매출 销售预计(客户别)'!$I$2 -> 0.007113265 | R25: =J25 -> ▼9 | S25: =VLOOKUP(B25,$T$2:$T$31,1,0) -> KFZ | T25: KVK | U25: =VLOOKUP(T25,$B$2:$B$33,1,0) -> #N/A
A26: 23 | B26: SAT | C26: 线下 | F26: 2861.73 | G26: 0 | H26: 0 | I26: 1317.9053 | J26: ▲96 | K26: =F26/1000 -> 2.86173 | L26: =H26/1000 -> 0 | M26: =IFERROR(G26/1000,0) -> 0 | N26: =I26/1000 -> 1.3179053 | O26: - | P26: =N26/L26 -> #DIV/0! | Q26: =Sheet1!I26/'26년 고객사별 예상 매출 销售预计(客户别)'!$I$2 -> 0.0066581286 | R26: =J26 -> ▲96 | S26: =VLOOKUP(B26,$T$2:$T$31,1,0) -> #N/A | T26: WXJ | U26: =VLOOKUP(T26,$B$2:$B$33,1,0) -> WXJ
A27: 24 | B27: HZH | C27: 线上 | D27: ● | F27: 0 | G27: 0 | H27: 0 | I27: 1231.7753 | J27: ▲95 | K27: =F27/1000 -> 0 | L27: =H27/1000 -> 0 | M27: =IFERROR(G27/1000,0) -> 0 | N27: =I27/1000 -> 1.2317753 | O27: =(N27-M27)/M27 -> #DIV/0! | P27: =N27/L27 -> #DIV/0! | Q27: =Sheet1!I27/'26년 고객사별 예상 매출 销售预计(客户别)'!$I$2 -> 0.0062229954 | R27: =J27 -> ▲95 | S27: =VLOOKUP(B27,$T$2:$T$31,1,0) -> #N/A | T27: JMS | U27: =VLOOKUP(T27,$B$2:$B$33,1,0) -> JMS
A28: 25 | B28: JMS | C28: 红人 | F28: 6498.92 | G28: 1674.84 | H28: 7000 | I28: 1216.3255 | J28: ▼7 | K28: =F28/1000 -> 6.49892 | L28: =H28/1000 -> 7 | M28: =IFERROR(G28/1000,0) -> 1.67484 | N28: =I28/1000 -> 1.2163255 | O28: =(N28-M28)/M28 -> -0.27376617 | P28: =N28/L28 -> 0.17376078 | Q28: =Sheet1!I28/'26년 고객사별 예상 매출 销售预计(客户别)'!$I$2 -> 0.0061449418 | R28: =J28 -> ▼7 | S28: =VLOOKUP(B28,$T$2:$T$31,1,0) -> JMS | T28: GSR | U28: =VLOOKUP(T28,$B$2:$B$33,1,0) -> #N/A
A29: 26 | B29: MZS | C29: 线上 | F29: 4261.25 | G29: 1116.31 | H29: 0 | I29: 1112.8484 | J29: - | K29: =F29/1000 -> 4.26125 | L29: =H29/1000 -> 0 | M29: =IFERROR(G29/1000,0) -> 1.11631 | N29: =I29/1000 -> 1.1128484 | O29: - | P29: =N29/L29 -> #DIV/0! | Q29: =Sheet1!I29/'26년 고객사별 예상 매출 销售预计(客户别)'!$I$2 -> 0.0056221701 | R29: =J29 -> - | S29: =VLOOKUP(B29,$T$2:$T$31,1,0) -> #N/A | T29: FIR | U29: =VLOOKUP(T29,$B$2:$B$33,1,0) -> #N/A
A30: 27 | B30: DSM | C30: 红人 | E30: ★ | F30: 359.05 | G30: 0 | H30: 0 | I30: 1075.7306 | J30: ▲92 | K30: =F30/1000 -> 0.35905 | L30: =H30/1000 -> 0 | M30: =IFERROR(G30/1000,0) -> 0 | N30: =I30/1000 -> 1.0757306 | O30: - | P30: =N30/L30 -> #DIV/0! | Q30: =Sheet1!I30/'26년 고객사별 예상 매출 销售预计(客户别)'!$I$2 -> 0.0054346488 | R30: =J30 -> ▲92 | S30: =VLOOKUP(B30,$T$2:$T$31,1,0) -> #N/A | T30: KFZ | U30: =VLOOKUP(T30,$B$2:$B$33,1,0) -> KFZ
A31: 28 | B31: KZQ | C31: 红人 | F31: 798.42 | G31: 622.02 | H31: 0 | I31: 1013.3172 | J31: ▲10 | K31: =F31/1000 -> 0.79842 | L31: =H31/1000 -> 0 | M31: =IFERROR(G31/1000,0) -> 0.62202 | N31: =I31/1000 -> 1.0133172 | O31: - | P31: =N31/L31 -> #DIV/0! | Q31: =Sheet1!I31/'26년 고객사별 예상 매출 销售预计(客户别)'!$I$2 -> 0.005119333 | R31: =J31 -> ▲10 | S31: =VLOOKUP(B31,$T$2:$T$31,1,0) -> #N/A | T31: VCI | U31: =VLOOKUP(T31,$B$2:$B$33,1,0) -> VCI
A32: 29 | B32: DJD | C32: 线上 | F32: 2064.79 | G32: 530.98 | H32: 0 | I32: 923.80069 | J32: ▲14 | K32: =F32/1000 -> 2.06479 | L32: =H32/1000 -> 0 | M32: =IFERROR(G32/1000,0) -> 0.53098 | N32: =I32/1000 -> 0.92380069 | O32: - | P32: =N32/L32 -> #DIV/0! | Q32: =Sheet1!I32/'26년 고객사별 예상 매출 销售预计(客户别)'!$I$2 -> 0.0046670909 | R32: =J32 -> ▲14 | S32: =VLOOKUP(B32,$T$2:$T$31,1,0) -> #N/A
A33: 30 | B33: PIM | C33: 线下 | D33: ● | F33: 512.8 | G33: 123.15 | H33: 0 | I33: 891.75856 | J33: ▲56 | K33: =F33/1000 -> 0.5128 | L33: =H33/1000 -> 0 | M33: =IFERROR(G33/1000,0) -> 0.12315 | N33: =I33/1000 -> 0.89175856 | O33: - | P33: =N33/L33 -> #DIV/0! | Q33: =Sheet1!I33/'26년 고객사별 예상 매출 销售预计(客户别)'!$I$2 -> 0.0045052123 | R33: =J33 -> ▲56 | S33: =VLOOKUP(B33,$T$2:$T$31,1,0) -> #N/A
A34: TOP 10 고객사 합계 | N34: 133 | Q34: 0.67
A35: TOP 20 고객사 합계 | N35: 157 | Q35: 0.79
A36: TOP 30 고객사 합계 | N36: 169 | Q36: 0.85

Sheet Sheet2
A1: 序号 | B1: 新客户 | C1: 最初销售日期 | D1: 渠道明细 | E1: 渠道归类 | F1: 集团 | G1: 25年实绩 | H1: 25년순위
A2: 1 | B2: N | C2: 45499 | D2: 抖音 快手 天猫 淘宝 得物 | E2: 线上 | F2: ZPX | G2: 120257.59 | H2: 1
A3: 2 | B3: N | C3: 44389 | D3: 东南亚 | E3: 出口 | F3: GFM | G3: 66437.821 | H3: 2
A4: 13 | B4: N | F4: JV-其他 | G4: 40255.423 | H4: 3
A5: 23 | B5: N | C5: 44820 | D5: 抖音 | E5: 红人 | F5: JJH | G5: 35865.773 | H5: 4
A6: 6 | B6: N | C6: 44223 | D6: 全渠道 | E6: 线上 | F6: DTA | G6: 30994.684 | H6: 5
A7: 3 | B7: N | C7: 44851 | D7: 微信代理+直播+私域 | E7: 线上 | F7: YBA | G7: 27224.18 | H7: 6
A8: 7 | B8: N | C8: 45518 | D8: 会员商店、山姆APP、京东 | E8: 线下 | F8: SAM | G8: 21123.134 | H8: 7
A9: 12 | B9: N | C9: 42674 | D9: 国内门店 | E9: 线下 | F9: MNS | G9: 20159.865 | H9: 8
A10: 17 | B10: N | C10: 44124 | D10: 快手 | E10: 红人 | F10: MIN | G10: 19890.634 | H10: 9
A11: 10 | B11: N | C11: 42487 | D11: 淘宝/快手 | E11: 红人 | F11: ATA | G11: 17704.788 | H11: 10
A12: 115 | B12: N | C12: 45606 | D12: 快手 | E12: 红人 | F12: XUK | G12: 12697.683 | H12: 11
A13: 116 | B13: N | C13: 44222 | D13: 抖音 | E13: 红人 | F13: MJE | G13: 11953.572 | H13: 12
A14: 8 | B14: N | C14: 45548 | D14: 抖音 | E14: 红人 | F14: WDL | G14: 10543.264 | H14: 13
A15: 21 | B15: N | C15: 44921 | D15: 抖音 | E15: 红人 | F15: KFZ | G15: 7956.6325 | H15: 14
A16: 41 | B16: N | C16: 45058 | D16: 抖音 | E16: 红人 | F16: JRQ | G16: 7375.044 | H16: 15
... A20: 24 | B20: N | C20: 45052 | D20: 快手 | E20: 红人 | F20: JMS | G20: 6498.9209 | H20: 19
A21: 20 | B21: N | F21: 其他 | G21: 5070.659 | H21: 20
A22: 27 | B22: N | C22: 42273 | D22: 美容院 | E22: 线下 | F22: ZLS | G22: 4978.5091 | H22: 21
A23: 32 | B23: N | C23: 45406 | D23: 私域 | E23: 线上 | F23: DDY | G23: 4928.8574 | H23: 22
A24: 26 | B24: N | C24: 42216 | D24: 抖音、快手、淘宝、得物、拼多多、线下彩妆集合店、出口东南亚 | E24: 线上 | F24: VCI | G24: 4920.3939 | H24: 23
A25: 29 | B25: N | C25: 45110 | D25: 线上：微商。线下：商场 | E25: 线上 | F25: MZS | G25: 4261.2458 | H25: 24
A26: 50 | B26: N | C26: 41647 | D26: 天猫、淘宝 | E26: 线下 | F26: CSL | G26: 4007.3238 | H26: 25
A27: 47 | B27: N | C27: 44166 | D27: 私域APP | E27: 线上 | F27: SDK | G27: 3911.1281 | H27: 26
A28: 117 | B28: N | C28: 44469 | D28: 线上全渠道、CS渠道、专卖店,出口东南亚 | E28: 线上 | F28: WDO | G28: 3807.4984 | H28: 27
A29: 16 | B29: N | C29: 45831 | D29: 线上（抖音快手）/线下（商超） | E29: 线上 | F29: HLR | G29: 3361.9688 | H29: 28
A30: 53 | B30: N | C30: 43930 | D30: 四五线城市美妆店 | E30: 线下 | F30: HYX | G30: 3227.6098 | H30: 29
A31: 40 | B31: N | C31: 45898 | D31: 抖音 | E31: 红人 | F31: YWH | G31: 3053.5508 | H31: 30
A32: 25 | B32: N | C32: 45416 | D32: 线下美容院 | E32: 线下 | F32: SAT | G32: 2861.7274 | H32: 31
A33: 69 | B33: N | C33: 43936 | D33: 抖音快手（分销），出口东南亚 | E33: 线上 | F33: CIY | G33: 2727.0586 | H33: 32
... A164: 112 | B164: N | C164: 46013 | D164: 私域 | E164: 线上 | F164: WZM | G164: 85.813 | H164: 163
A165: 80 | B165: N | C165: 45953 | E165: 出口 | F165: HMH | G165: 81.05628 | H165: 164
A166: 184 | B166: N | C166: 45953 | D166: 线上/出口泰国 | E166: 出口 | F166: LUL | G166: 79.59824 | H166: 165
A167: 113 | B167: N | C167: 46006 | D167: 线下专业渠道 | E167: 线下 | F167: FLY | G167: 78.62039 | H167: 166
A168: 185 | B168: N | C168: 45455 | D168: 快手 | E168: 线上 | F168: SZR | G168: 77.80173 | H168: 167
A169: 186 | B169: N | C169: 45801 | D169: 线上（全渠道） | E169: 线上 | F169: XDK | G169: 69.34553 | H169: 168
A170: 187 | B170: N | C170: 45891 | D170: 抖音 | E170: 线上 | F170: LEE | G170: 66.05266 | H170: 169
A171: 188 | B171: N | C171: 44546 | D171: 淘宝/抖音/线下门店 | E171: 线上 | F171: SHB | G171: 64.42152 | H171: 170
A172: 189 | B172: N | C172: 45756 | D172: 抖音、快手、小红书 | E172: 线上 | F172: HEL | G172: 61.88869 | H172: 171
A173: 190 | B173: N | C173: 45804 | D173: 线上（快手） | E173: 红人 | F173: BZD | G173: 60.88469 | H173: 172
...
